<?xml version="1.0"?>

<robot xmlns:xacro="http://www.ros.org/wiki/xacro">

  <!-- Front Left Wheel -->
  <link name="front_left_wheel_link">
    <visual>
      <geometry>
        <cylinder radius="0.15" length="0.08"/>
      </geometry>
      <origin rpy="1.5708 0 0"/>
    </visual>
  </link>

  <!-- Front Right Wheel -->
  <link name="front_right_wheel_link">
    <visual>
      <geometry>
        <cylinder radius="0.15" length="0.08"/>
      </geometry>
      <origin rpy="1.5708 0 0"/>
    </visual>
  </link>

  <!-- Rear Left Wheel -->
  <link name="rear_left_wheel_link">
    <visual>
      <geometry>
        <cylinder radius="0.15" length="0.08"/>
      </geometry>
      <origin rpy="1.5708 0 0"/>
    </visual>
  </link>

  <!-- Rear Right Wheel -->
  <link name="rear_right_wheel_link">
    <visual>
      <geometry>
        <cylinder radius="0.15" length="0.08"/>
      </geometry>
      <origin rpy="1.5708 0 0"/>
    </visual>
  </link>

  <!-- Front Left Steering -->
  <joint name="front_left_steering_joint" type="revolute">
    <parent link="chassis_link"/>
    <child link="front_left_wheel_link"/>
    <origin xyz="0.45 0.35 -0.15"/>
    <axis xyz="0 0 1"/>
    <limit lower="-0.6" upper="0.6" effort="20" velocity="1.5"/>
  </joint>

  <!-- Front Right Steering -->
  <joint name="front_right_steering_joint" type="revolute">
    <parent link="chassis_link"/>
    <child link="front_right_wheel_link"/>
    <origin xyz="0.45 -0.35 -0.15"/>
    <axis xyz="0 0 1"/>
    <limit lower="-0.6" upper="0.6" effort="20" velocity="1.5"/>
  </joint>

  <!-- Rear Left Drive -->
  <joint name="rear_left_wheel_joint" type="continuous">
    <parent link="chassis_link"/>
    <child link="rear_left_wheel_link"/>
    <origin xyz="-0.45 0.35 -0.15"/>
    <axis xyz="0 1 0"/>
  </joint>

  <!-- Rear Right Drive -->
  <joint name="rear_right_wheel_joint" type="continuous">
    <parent link="chassis_link"/>
    <child link="rear_right_wheel_link"/>
    <origin xyz="-0.45 -0.35 -0.15"/>
    <axis xyz="0 1 0"/>
  </joint>

</robot>
